Workbook

Sheet Sheet1
B1: Name of the Fund
B2: UTI Nifty 50 Index Growth Direct Plan
B3: Parag Parikh Flexi Cap Growth Direct Plan
B4: Axis Corporate Bond Growth Direct Plan
B5: ICICI Prudential Equity & Debt Growth Direct Plan
B6: ICICI Prudential Short Term Growth Direct Plan
B7: UTI Nifty Next 50 Index Growth Direct Plan
B8: Nippon India Nifty Smallcap 250 Index Growth Direct Plan
B9: Motilal Oswal Nifty Midcap 150 Index Growth Direct Plan
B10: HDFC Balanced Advantage Growth Direct Plan
B11: SBI Medium To Long Duration Growth Direct Plan
B12: HDFC Small Cap Growth Direct Plan
... B94: HDFC Balanced Growth Plan

Sheet txns
A1: Date | B1: Folio Number | C1: AMFI code | D1: ISIN code | E1: Name of the Fund | F1: Order | G1: Units | H1: NAV | I1: Current Nav | J1: Amount (INR)
A2: 2026-02-11 | B2: 577383970916 | C2: =_xlfn.XLOOKUP(E2,Sheet8!A:A,Sheet8!D:D,"NA") -> 120716 | D2: =_xlfn.XLOOKUP(E2,Sheet8!A:A,Sheet8!E:E,"NA") -> INF789F01XA0 | E2: UTI Nifty 50 Index Growth Direct Plan | F2: buy | G2: 55.108 | H2: 181.4539 | I2: 178.7925 | J2: 9999.5
A3: 2026-02-11 | B3: 18542903 | C3: =_xlfn.XLOOKUP(E3,Sheet8!A:A,Sheet8!D:D,"NA") -> 122639 | D3: =_xlfn.XLOOKUP(E3,Sheet8!A:A,Sheet8!E:E,"NA") -> INF879O01027 | E3: Parag Parikh Flexi Cap Growth Direct Plan | F3: buy | G3: 53.301 | H3: 93.8017 | I3: 92.9299 | J3: 4999.75
A4: 2026-02-11 | B4: 91081817545 | C4: =_xlfn.XLOOKUP(E4,Sheet8!A:A,Sheet8!D:D,"NA") -> 141588 | D4: =_xlfn.XLOOKUP(E4,Sheet8!A:A,Sheet8!E:E,"NA") -> INF846K01ZM8 | E4: Axis Corporate Bond Growth Direct Plan | F4: buy | G4: 267.119 | H4: 18.7173 | I4: 18.7785 | J4: 4999.75
A5: 2026-02-11 | B5: 41440972/44 | C5: =_xlfn.XLOOKUP(E5,Sheet8!A:A,Sheet8!D:D,"NA") -> 120251 | D5: =_xlfn.XLOOKUP(E5,Sheet8!A:A,Sheet8!E:E,"NA") -> INF109K01Y07 | E5: ICICI Prudential Equity & Debt Growth Direct Plan | F5: buy | G5: 16.283 | H5: 460.59 | I5: 455.44 | J5: 7499.63
A6: 2026-02-11 | B6: 41440972/44 | C6: =_xlfn.XLOOKUP(E6,Sheet8!A:A,Sheet8!D:D,"NA") -> 120754 | D6: =_xlfn.XLOOKUP(E6,Sheet8!A:A,Sheet8!E:E,"NA") -> INF109K013N3 | E6: ICICI Prudential Short Term Growth Direct Plan | F6: buy | G6: 43.97 | H6: 68.2245 | I6: 68.3894 | J6: 2999.85
A7: 2026-01-12 | B7: 577383970916 | C7: =_xlfn.XLOOKUP(E7,Sheet8!A:A,Sheet8!D:D,"NA") -> 120716 | D7: =_xlfn.XLOOKUP(E7,Sheet8!A:A,Sheet8!E:E,"NA") -> INF789F01XA0 | E7: UTI Nifty 50 Index Growth Direct Plan | F7: buy | G7: 55.502 | H7: 180.1659 | I7: 178.7925 | J7: 9999.5
A8: 2026-01-12 | B8: 18542903 | C8: =_xlfn.XLOOKUP(E8,Sheet8!A:A,Sheet8!D:D,"NA") -> 122639 | D8: =_xlfn.XLOOKUP(E8,Sheet8!A:A,Sheet8!E:E,"NA") -> INF879O01027 | E8: Parag Parikh Flexi Cap Growth Direct Plan | F8: buy | G8: 53.003 | H8: 94.329 | I8: 92.9299 | J8: 4999.75
A9: 2026-01-12 | B9: 41440972/44 | C9: =_xlfn.XLOOKUP(E9,Sheet8!A:A,Sheet8!D:D,"NA") -> 120754 | D9: =_xlfn.XLOOKUP(E9,Sheet8!A:A,Sheet8!E:E,"NA") -> INF109K013N3 | E9: ICICI Prudential Short Term Growth Direct Plan | F9: buy | G9: 44.113 | H9: 68.0034 | I9: 68.3894 | J9: 2999.85
A10: 2026-01-12 | B10: 41440972/44 | C10: =_xlfn.XLOOKUP(E10,Sheet8!A:A,Sheet8!D:D,"NA") -> 120251 | D10: =_xlfn.XLOOKUP(E10,Sheet8!A:A,Sheet8!E:E,"NA") -> INF109K01Y07 | E10: ICICI Prudential Equity & Debt Growth Direct Plan | F10: buy | G10: 16.514 | H10: 454.14 | I10: 455.44 | J10: 7499.63
A11: 2026-01-12 | B11: 91081817545 | C11: =_xlfn.XLOOKUP(E11,Sheet8!A:A,Sheet8!D:D,"NA") -> 141588 | D11: =_xlfn.XLOOKUP(E11,Sheet8!A:A,Sheet8!E:E,"NA") -> INF846K01ZM8 | E11: Axis Corporate Bond Growth Direct Plan | F11: buy | G11: 267.716 | H11: 18.6756 | I11: 18.7785 | J11: 4999.75
A12: 2025-12-11 | B12: 577383970207 | C12: =_xlfn.XLOOKUP(E12,Sheet8!A:A,Sheet8!D:D,"NA") -> 143341 | D12: =_xlfn.XLOOKUP(E12,Sheet8!A:A,Sheet8!E:E,"NA") -> INF789FC12T1 | E12: UTI Nifty Next 50 Index Growth Direct Plan | F12: buy | G12: 199.07 | H12: 25.1155 | I12: 25.6899 | J12: 4999.75
A13: 2025-12-11 | B13: 577383970916 | C13: =_xlfn.XLOOKUP(E13,Sheet8!A:A,Sheet8!D:D,"NA") -> 120716 | D13: =_xlfn.XLOOKUP(E13,Sheet8!A:A,Sheet8!E:E,"NA") -> INF789F01XA0 | E13: UTI Nifty 50 Index Growth Direct Plan | F13: buy | G13: 55.258 | H13: 180.9594 | I13: 178.7925 | J13: 9999.5
A14: 2025-12-11 | B14: 18542903 | C14: =_xlfn.XLOOKUP(E14,Sheet8!A:A,Sheet8!D:D,"NA") -> 122639 | D14: =_xlfn.XLOOKUP(E14,Sheet8!A:A,Sheet8!E:E,"NA") -> INF879O01027 | E14: Parag Parikh Flexi Cap Growth Direct Plan | F14: buy | G14: 52.776 | H14: 94.735 | I14: 92.9299 | J14: 4999.75
A15: 2025-12-11 | B15: 488218776753 | C15: =_xlfn.XLOOKUP(E15,Sheet8!A:A,Sheet8!D:D,"NA") -> 148519 | D15: =_xlfn.XLOOKUP(E15,Sheet8!A:A,Sheet8!E:E,"NA") -> INF204KB15W0 | E15: Nippon India Nifty Smallcap 250 Index Growth Direct Plan | F15: buy | G15: 124.175 | H15: 32.2109 | I15: 31.6237 | J15: 3999.8
A16: 2025-12-11 | B16: 91012748842 | C16: =_xlfn.XLOOKUP(E16,Sheet8!A:A,Sheet8!D:D,"NA") -> 147622 | D16: =_xlfn.XLOOKUP(E16,Sheet8!A:A,Sheet8!E:E,"NA") -> INF247L01916 | E16: Motilal Oswal Nifty Midcap 150 Index Growth Direct Plan | F16: buy | G16: 126.26 | H16: 39.5987 | I16: 39.7003 | J16: 4999.75
A17: 2025-12-11 | B17: 41440972/44 | C17: =_xlfn.XLOOKUP(E17,Sheet8!A:A,Sheet8!D:D,"NA") -> 120754 | D17: =_xlfn.XLOOKUP(E17,Sheet8!A:A,Sheet8!E:E,"NA") -> INF109K013N3 | E17: ICICI Prudential Short Term Growth Direct Plan | F17: buy | G17: 44.281 | H17: 67.745 | I17: 68.3894 | J17: 2999.85
A18: 2025-12-11 | B18: 41440972/44 | C18: =_xlfn.XLOOKUP(E18,Sheet8!A:A,Sheet8!D:D,"NA") -> 120251 | D18: =_xlfn.XLOOKUP(E18,Sheet8!A:A,Sheet8!E:E,"NA") -> INF109K01Y07 | E18: ICICI Prudential Equity & Debt Growth Direct Plan | F18: buy | G18: 16.509 | H18: 454.28 | I18: 455.44 | J18: 7499.63
A19: 2025-12-11 | B19: 10372451/53 | C19: =_xlfn.XLOOKUP(E19,Sheet8!A:A,Sheet8!D:D,"NA") -> 118968 | D19: =_xlfn.XLOOKUP(E19,Sheet8!A:A,Sheet8!E:E,"NA") -> INF179K01WA6 | E19: HDFC Balanced Advantage Growth Direct Plan | F19: buy | G19: 8.711 | H19: 573.959 | I19: 576.21 | J19: 4999.75
A20: 2025-12-11 | B20: 91081817545 | C20: =_xlfn.XLOOKUP(E20,Sheet8!A:A,Sheet8!D:D,"NA") -> 141588 | D20: =_xlfn.XLOOKUP(E20,Sheet8!A:A,Sheet8!E:E,"NA") -> INF846K01ZM8 | E20: Axis Corporate Bond Growth Direct Plan | F20: buy | G20: 268.574 | H20: 18.6159 | I20: 18.7785 | J20: 4999.75
A21: 2025-11-11 | B21: 91081817545 | C21: =_xlfn.XLOOKUP(E21,Sheet8!A:A,Sheet8!D:D,"NA") -> 141588 | D21: =_xlfn.XLOOKUP(E21,Sheet8!A:A,Sheet8!E:E,"NA") -> INF846K01ZM8 | E21: Axis Corporate Bond Growth Direct Plan | F21: buy | G21: 268.921 | H21: 18.5919 | I21: 18.7785 | J21: 4999.75
A22: 2025-11-11 | B22: 577383970207 | C22: =_xlfn.XLOOKUP(E22,Sheet8!A:A,Sheet8!D:D,"NA") -> 143341 | D22: =_xlfn.XLOOKUP(E22,Sheet8!A:A,Sheet8!E:E,"NA") -> INF789FC12T1 | E22: UTI Nifty Next 50 Index Growth Direct Plan | F22: buy | G22: 193.994 | H22: 25.7727 | I22: 25.6899 | J22: 4999.75
A23: 2025-11-11 | B23: 577383970916 | C23: =_xlfn.XLOOKUP(E23,Sheet8!A:A,Sheet8!D:D,"NA") -> 120716 | D23: =_xlfn.XLOOKUP(E23,Sheet8!A:A,Sheet8!E:E,"NA") -> INF789F01XA0 | E23: UTI Nifty 50 Index Growth Direct Plan | F23: buy | G23: 55.696 | H23: 179.5365 | I23: 178.7925 | J23: 9999.5
A24: 2025-11-11 | B24: 18542903 | C24: =_xlfn.XLOOKUP(E24,Sheet8!A:A,Sheet8!D:D,"NA") -> 122639 | D24: =_xlfn.XLOOKUP(E24,Sheet8!A:A,Sheet8!E:E,"NA") -> INF879O01027 | E24: Parag Parikh Flexi Cap Growth Direct Plan | F24: buy | G24: 53.087 | H24: 94.1798 | I24: 92.9299 | J24: 4999.75
A25: 2025-11-11 | B25: 488218776753 | C25: =_xlfn.XLOOKUP(E25,Sheet8!A:A,Sheet8!D:D,"NA") -> 148519 | D25: =_xlfn.XLOOKUP(E25,Sheet8!A:A,Sheet8!E:E,"NA") -> INF204KB15W0 | E25: Nippon India Nifty Smallcap 250 Index Growth Direct Plan | F25: buy | G25: 118.844 | H25: 33.6559 | I25: 31.6237 | J25: 3999.8
A26: 2025-11-11 | B26: 91012748842 | C26: =_xlfn.XLOOKUP(E26,Sheet8!A:A,Sheet8!D:D,"NA") -> 147622 | D26: =_xlfn.XLOOKUP(E26,Sheet8!A:A,Sheet8!E:E,"NA") -> INF247L01916 | E26: Motilal Oswal Nifty Midcap 150 Index Growth Direct Plan | F26: buy | G26: 124.42 | H26: 40.1843 | I26: 39.7003 | J26: 4999.75
A27: 2025-11-11 | B27: 41440972/44 | C27: =_xlfn.XLOOKUP(E27,Sheet8!A:A,Sheet8!D:D,"NA") -> 120754 | D27: =_xlfn.XLOOKUP(E27,Sheet8!A:A,Sheet8!E:E,"NA") -> INF109K013N3 | E27: ICICI Prudential Short Term Growth Direct Plan | F27: buy | G27: 44.417 | H27: 67.538 | I27: 68.3894 | J27: 2999.85
A28: 2025-11-11 | B28: 41440972/44 | C28: =_xlfn.XLOOKUP(E28,Sheet8!A:A,Sheet8!D:D,"NA") -> 120251 | D28: =_xlfn.XLOOKUP(E28,Sheet8!A:A,Sheet8!E:E,"NA") -> INF109K01Y07 | E28: ICICI Prudential Equity & Debt Growth Direct Plan | F28: buy | G28: 16.581 | H28: 452.31 | I28: 455.44 | J28: 7499.63
A29: 2025-11-11 | B29: 10372451/53 | C29: =_xlfn.XLOOKUP(E29,Sheet8!A:A,Sheet8!D:D,"NA") -> 118968 | D29: =_xlfn.XLOOKUP(E29,Sheet8!A:A,Sheet8!E:E,"NA") -> INF179K01WA6 | E29: HDFC Balanced Advantage Growth Direct Plan | F29: buy | G29: 8.687 | H29: 575.546 | I29: 576.21 | J29: 4999.75
A30: 2025-11-03 | B30: 28647750 | C30: =_xlfn.XLOOKUP(E30,Sheet8!A:A,Sheet8!D:D,"NA") -> 119713 | D30: =_xlfn.XLOOKUP(E30,Sheet8!A:A,Sheet8!E:E,"NA") -> INF200K01SP6 | E30: SBI Medium To Long Duration Growth Direct Plan | F30: buy | G30: 64.679 | H30: 77.3008 | I30: 77.9586 | J30: 4999.75
A31: 2025-10-13 | B31: 11104373/76 | C31: =_xlfn.XLOOKUP(E31,Sheet8!A:A,Sheet8!D:D,"NA") -> 130503 | D31: =_xlfn.XLOOKUP(E31,Sheet8!A:A,Sheet8!E:E,"NA") -> INF179KA1RW5 | E31: HDFC Small Cap Growth Direct Plan | F31: buy | G31: 1549.157 | H31: 161.37 | I31: 153.431 | J31: 249987.5
A32: 2025-10-13 | B32: 24222120 | C32: =_xlfn.XLOOKUP(E32,Sheet8!A:A,Sheet8!D:D,"NA") -> 149134 | D32: =_xlfn.XLOOKUP(E32,Sheet8!A:A,Sheet8!E:E,"NA") -> INF200KA1Y73 | E32: SBI Balanced Advantage Growth Direct Plan | F32: buy | G32: 24758.592 | H32: 16.1552 | I32: 16.7701 | J32: 399980
A33: 2025-10-13 | B33: 91062128393 | C33: =_xlfn.XLOOKUP(E33,Sheet8!A:A,Sheet8!D:D,"NA") -> 141588 | D33: =_xlfn.XLOOKUP(E33,Sheet8!A:A,Sheet8!E:E,"NA") -> INF846K01ZM8 | E33: Axis Corporate Bond Growth Direct Plan | F33: buy | G33: 81662.565 | H33: 18.4898 | I33: 18.7785 | J33: 1509924.5
A34: 2025-10-13 | B34: 91062128393 | C34: =_xlfn.XLOOKUP(E34,Sheet8!A:A,Sheet8!D:D,"NA") -> 149466 | D34: =_xlfn.XLOOKUP(E34,Sheet8!A:A,Sheet8!E:E,"NA") -> INF846K019E7 | E34: Axis Nifty Next 50 Index Growth Direct Plan | F34: buy | G34: 36643.36 | H34: 16.919 | I34: 17.1709 | J34: 619969
A35: 2025-10-13 | B35: 599295234843 | C35: =_xlfn.XLOOKUP(E35,Sheet8!A:A,Sheet8!D:D,"NA") -> 120716 | D35: =_xlfn.XLOOKUP(E35,Sheet8!A:A,Sheet8!E:E,"NA") -> INF789F01XA0 | E35: UTI Nifty 50 Index Growth Direct Plan | F35: buy | G35: 11360.951 | H35: 176.0328 | I35: 178.7925 | J35: 1999900
A36: 2025-10-13 | B36: 8841618/87 | C36: =_xlfn.XLOOKUP(E36,Sheet8!A:A,Sheet8!D:D,"NA") -> 120616 | D36: =_xlfn.XLOOKUP(E36,Sheet8!A:A,Sheet8!E:E,"NA") -> INF109K01S39 | E36: ICICI Prudential Regular Saving Growth Direct Plan | F36: buy | G36: 3529.742 | H36: 84.9878 | I36: 86.0312 | J36: 299985
A37: 2025-10-13 | B37: 11104373/76 | C37: =_xlfn.XLOOKUP(E37,Sheet8!A:A,Sheet8!D:D,"NA") -> 118955 | D37: =_xlfn.XLOOKUP(E37,Sheet8!A:A,Sheet8!E:E,"NA") -> INF179K01UT0 | E37: HDFC Flexicap Growth Direct Plan | F37: buy | G37: 80.308 | H37: 2241.258 | I37: 2282.94 | J37: 179991
A38: 2025-10-13 | B38: 11104373/76 | C38: =_xlfn.XLOOKUP(E38,Sheet8!A:A,Sheet8!D:D,"NA") -> 118950 | D38: =_xlfn.XLOOKUP(E38,Sheet8!A:A,Sheet8!E:E,"NA") -> INF179K01VK7 | E38: HDFC Focused Growth Direct Plan | F38: buy | G38: 372.231 | H38: 268.637 | I38: 274.182 | J38: 99995
A39: 2025-10-07 | B39: 13993567/26 | C39: =_xlfn.XLOOKUP(E39,Sheet8!A:A,Sheet8!D:D,"NA") -> 146010 | D39: =_xlfn.XLOOKUP(E39,Sheet8!A:A,Sheet8!E:E,"NA") -> INF277K013S8 | E39: Tata Balanced Advantage Growth Direct Plan | F39: buy | G39: 14697.598 | H39: 22.7917 | I39: 23.3771 | J39: 334983.25
A40: 2025-10-07 | B40: 3556322/64 | C40: =_xlfn.XLOOKUP(E40,Sheet8!A:A,Sheet8!D:D,"NA") -> 146010 | D40: =_xlfn.XLOOKUP(E40,Sheet8!A:A,Sheet8!E:E,"NA") -> INF277K013S8 | E40: Tata Balanced Advantage Growth Direct Plan | F40: buy | G40: 14697.598 | H40: 22.7917 | I40: 23.3771 | J40: 334983.25
...

Sheet Sheet8
A2: Axis Nifty Next 50 Index Growth Direct Plan | B2: 120377 | C2: INF846K01D22 | D2: 149466 | E2: INF846K019E7
A3: SBI Balanced Advantage Growth Direct Plan | B3: 149453 | C3: INF754K01HL9 | D3: 149134 | E3: INF200KA1Y73
A4: ICICI Prudential Regular Saving Growth Direct Plan | B4: 120438 | C4: INF109K01X46 | D4: 120616 | E4: INF109K01S39
A5: UTI Value Growth Direct Plan | B5: 119948 | C5: INF209K01V26 | D5: 120751 | E5: INF789F01VB2
A6: HDFC Corporate Bond Growth Direct Plan | B6: 120046 | C6: INF179K01XY2 | D6: 118987 | E6: INF179K01XD8
A7: SBI Focused Growth Direct Plan | B7: 120516 | C7: INF754K01629 | D7: 119727 | E7: INF200K01RJ1
A8: Motilal Oswal Nifty Midcap 150 Index Growth Direct Plan | B8: 147113 | C8: INF247L01AF9 | D8: 147622 | E8: INF247L01916
A9: Canara Robeco Large Cap Growth Direct Plan | B9: 120586 | C9: INF209K01YY7 | D9: 118269 | E9: INF760K01FR2
A10: Axis Focused Growth Direct Plan | D10: 120468 | E10: INF846K01CQ8
A11: ICICI Prudential Short Term Growth Direct Plan | D11: 120754 | E11: INF109K013N3
A12: Canara Robeco Flexi Cap Growth Direct Plan | D12: 118275 | E12: INF760K01EF0
A13: Aditya Birla Sun Life Dynamic Bond Retail Growth Plan | D13: 102767 | E13: INF209K01793
A14: Aditya Birla Sun Life Floating Rate Regular Growth Plan | D14: 122644 | E14: INF209K01MG9
A15: Aditya Birla Sun Life Large Cap Growth Plan | D15: 103174 | E15: INF209K01BR9
A16: Aditya Birla Sun Life Short Term Growth Plan | D16: 101843 | E16: INF209K01975
A17: Axis Corporate Bond Growth Direct Plan | D17: 141588 | E17: INF846K01ZM8
A18: Axis Dynamic Bond Growth Direct Plan | D18: 115068 | E18: INF846K01917
A19: Axis Focused Regular Growth Plan | D19: 120468 | E19: INF846K01CQ8
A20: Axis Large Cap Growth Direct Plan | D20: 120466 | E20: INF846K01DN3
A21: Axis Large Cap Regular Growth Plan | D21: 112277 | E21: INF846K01164
... A88: UTI Value Regular Growth Plan | D88: 103098 | E88: INF789F01AG5

Sheet Sheet5
A1: MF names inth elsit | B1: #,Input Fund Name,Found Fund Name,AMFI Code,ISIN Code | C1: {=_xlfn.TEXTSPLIT(B1,",")} -> # | D1: Input Fund Name | E1: Found Fund Name | F1: AMFI Code | G1: ISIN Code | H1: AMFI Code | I1: ISIN Code
A2: Aditya Birla Sun Life Corporate Bond Regular Growth Plan | B2: 1,Aditya Birla Sun Life Corporate Bond Regular Growth Plan,ABSL Corporate Bond Fund-Regular Growth,103174,INF209K01BR9 | C2: {=_xlfn.TEXTSPLIT(B2,",")} -> 1 | D2: Aditya Birla Sun Life Corporate Bond Regular Growth Plan | E2: ABSL Corporate Bond Fund-Regular Growth | F2: 103174 | G2: INF209K01BR9 | H2: 103174 | I2: INF209K01BR9
A3: Aditya Birla Sun Life Dynamic Bond Retail Growth Plan | B3: 2,Aditya Birla Sun Life Dynamic Bond Retail Growth Plan,ABSL Dynamic Bond Fund-Regular Growth,103176,INF209K01BT5 | C3: {=_xlfn.TEXTSPLIT(B3,",")} -> 2 | D3: Aditya Birla Sun Life Dynamic Bond Retail Growth Plan | E3: ABSL Dynamic Bond Fund-Regular Growth | F3: 103176 | G3: INF209K01BT5 | H3: 103176 | I3: INF209K01BT5
A4: Aditya Birla Sun Life Floating Rate Regular Growth Plan | B4: 3,Aditya Birla Sun Life Floating Rate Regular Growth Plan,ABSL Floating Rate Fund-Regular Growth,103168,INF209K01BO6 | C4: {=_xlfn.TEXTSPLIT(B4,",")} -> 3 | D4: Aditya Birla Sun Life Floating Rate Regular Growth Plan | E4: ABSL Floating Rate Fund-Regular Growth | F4: 103168 | G4: INF209K01BO6 | H4: 103168 | I4: INF209K01BO6
A5: Aditya Birla Sun Life Large Cap Growth Plan | B5: 4,Aditya Birla Sun Life Large Cap Growth Plan,ABSL Large Cap Fund-Regular Growth,103173,INF209K01BR9 | C5: {=_xlfn.TEXTSPLIT(B5,",")} -> 4 | D5: Aditya Birla Sun Life Large Cap Growth Plan | E5: ABSL Large Cap Fund-Regular Growth | F5: 103173 | G5: INF209K01BR9 | H5: 103173 | I5: INF209K01BR9
A6: Aditya Birla Sun Life Medium Term Growth Plan | B6: 5,Aditya Birla Sun Life Medium Term Growth Plan,ABSL Medium Term Plan-Regular Growth,110372,INF209K01565 | C6: {=_xlfn.TEXTSPLIT(B6,",")} -> 5 | D6: Aditya Birla Sun Life Medium Term Growth Plan | E6: ABSL Medium Term Plan-Regular Growth | F6: 110372 | G6: INF209K01565 | H6: 110372 | I6: INF209K01565
A7: Aditya Birla Sun Life Short Term Growth Plan | B7: 6,Aditya Birla Sun Life Short Term Growth Plan,ABSL Short Term Fund-Regular Growth,103172,INF209K01BP3 | C7: {=_xlfn.TEXTSPLIT(B7,",")} -> 6 | D7: Aditya Birla Sun Life Short Term Growth Plan | E7: ABSL Short Term Fund-Regular Growth | F7: 103172 | G7: INF209K01BP3 | H7: 103172 | I7: INF209K01BP3
A8: Axis Corporate Bond Growth Direct Plan | B8: 7,Axis Corporate Bond Growth Direct Plan,Axis Corporate Bond Fund-Direct Growth,141589,INF846K01X36 | C8: {=_xlfn.TEXTSPLIT(B8,",")} -> 7 | D8: Axis Corporate Bond Growth Direct Plan | E8: Axis Corporate Bond Fund-Direct Growth | F8: 141589 | G8: INF846K01X36 | H8: 141589 | I8: INF846K01X36
A9: Axis Dynamic Bond Growth Direct Plan | B9: 8,Axis Dynamic Bond Growth Direct Plan,Axis Dynamic Bond Fund-Direct Growth,120361,INF846K01D55 | C9: {=_xlfn.TEXTSPLIT(B9,",")} -> 8 | D9: Axis Dynamic Bond Growth Direct Plan | E9: Axis Dynamic Bond Fund-Direct Growth | F9: 120361 | G9: INF846K01D55 | H9: 120361 | I9: INF846K01D55
A10: Axis Focused Growth Direct Plan | B10: 9,Axis Focused Growth Direct Plan,Axis Focused 25 Fund-Direct Growth,120377,INF846K01D22 | C10: {=_xlfn.TEXTSPLIT(B10,",")} -> 9 | D10: Axis Focused Growth Direct Plan | E10: Axis Focused 25 Fund-Direct Growth | F10: 120377 | G10: INF846K01D22 | H10: 120377 | I10: INF846K01D22
A11: Axis Focused Regular Growth Plan | B11: 10,Axis Focused Regular Growth Plan,Axis Focused 25 Fund-Regular Growth,117621,INF846K01CH7 | C11: {=_xlfn.TEXTSPLIT(B11,",")} -> 10 | D11: Axis Focused Regular Growth Plan | E11: Axis Focused 25 Fund-Regular Growth | F11: 117621 | G11: INF846K01CH7 | H11: 117621 | I11: INF846K01CH7
A12: Axis Large Cap Growth Direct Plan | B12: 11,Axis Large Cap Growth Direct Plan,Axis Large Cap Fund-Direct Growth,120353,INF846K01D48 | C12: {=_xlfn.TEXTSPLIT(B12,",")} -> 11 | D12: Axis Large Cap Growth Direct Plan | E12: Axis Large Cap Fund-Direct Growth | F12: 120353 | G12: INF846K01D48 | H12: 120353 | I12: INF846K01D48
... A91: HDFC Balanced Growth Plan | B91: 90,HDFC Balanced Growth Plan,HDFC Balanced Growth Plan- regular,100119,INF179K01830 | C91: {=_xlfn.TEXTSPLIT(B91,",")} -> 90 | D91: HDFC Balanced Growth Plan | E91: HDFC Balanced Growth Plan- regular | F91: 100119 | G91: INF179K01830 | H91: 100119 | I91: INF179K01830
